<?xml version="1.0"?> 
<robot xmlns:xacro="http://www.ros.org/wiki/xacro"> 

  <xacro:macro name="khi_rs005l" params="
    name
    parent
    *origin
    use_fake_hardware:=false
    tf_prefix
    generate_ros2_control_tag:=true
    sim_ignition:=false
    ">

    <xacro:if value="${generate_ros2_control_tag}">
      <!-- ros2 control include -->
      <xacro:include filename="$(find rs005l_description)/urdf/rs005l.ros2_control.xacro" />
      <!-- ros2 control instance -->
      <xacro:rs005l_ros2_control
        name="${name}"
        use_fake_hardware="${use_fake_hardware}"
        tf_prefix="${tf_prefix}"
        sim_ignition="${sim_ignition}"
      />
    </xacro:if> 

    <!-- ROS2: include path'leri find -> find-pkg-share -->
    <xacro:include filename="$(find mobile_manipulator_description)/urdf/khi_rs/rs.transmission.xacro" />
    <xacro:include filename="$(find mobile_manipulator_description)/urdf/khi_rs/common.gazebo.xacro" />

    <!-- link rviz colors -->
    <material name="White">
      <color rgba="1 1 1 1"/>
    </material>

    <material name="Black">
      <color rgba="0 0 0 1"/>
    </material>

    <material name="silver">
      <color rgba="0.7 0.7 0.7 1.0"/>
    </material>

    <!-- DH parameters -->
    <xacro:property name="dh_j1_j2_roty" value="${radians(90)}"/>
    <xacro:property name="dh_j3_j4_roty" value="${radians(90)}"/>
    <xacro:property name="dh_j4_j5_roty" value="${radians(90)}"/>
    <xacro:property name="dh_j5_j6_roty" value="${radians(90)}"/>

    <!-- link mass [kg] -->
    <xacro:property name="j0_mass" value="5.910"/>
    <xacro:property name="j1_mass" value="10.395"/>
    <xacro:property name="j2_mass" value="8.788"/>
    <xacro:property name="j3_mass" value="7.575"/>
    <xacro:property name="j4_mass" value="2.679"/>
    <xacro:property name="j5_mass" value="1.028"/>
    <xacro:property name="j6_mass" value="0.625"/>

    <!-- link lengths [m] -->
    <xacro:property name="j0_length" value="0.295"/>
    <xacro:property name="j1_length" value="0.105"/>
    <xacro:property name="j2_length" value="0.380"/>
    <xacro:property name="j31_length" value="0.15"/>
    <xacro:property name="j32_length" value="0.080"/>
    <xacro:property name="j4_length" value="0.410"/>
    <xacro:property name="j5_length" value="0.078"/>
    
    <!-- joint limits [rad] -->
    <xacro:property name="j1_lower_limit" value="${radians(-180)}"/>
    <xacro:property name="j1_upper_limit" value="${radians( 180)}"/>
    <xacro:property name="j2_lower_limit" value="${radians( -80)}"/>
    <xacro:property name="j2_upper_limit" value="${radians( 135)}"/>
    <xacro:property name="j3_lower_limit" value="${radians(-172)}"/>
    <xacro:property name="j3_upper_limit" value="${radians( 118)}"/>
    <xacro:property name="j4_lower_limit" value="${radians(-360)}"/>
    <xacro:property name="j4_upper_limit" value="${radians( 360)}"/>
    <xacro:property name="j5_lower_limit" value="${radians(-145)}"/>
    <xacro:property name="j5_upper_limit" value="${radians( 145)}"/>
    <xacro:property name="j6_lower_limit" value="${radians(-360)}"/>
    <xacro:property name="j6_upper_limit" value="${radians( 360)}"/>

    <!-- joint velocity limits [rad/s] -->
    <xacro:property name="j1_velocity_limit" value="${radians( 300)}"/>
    <xacro:property name="j2_velocity_limit" value="${radians( 300)}"/>
    <xacro:property name="j3_velocity_limit" value="${radians( 300)}"/>
    <xacro:property name="j4_velocity_limit" value="${radians( 460)}"/>
    <xacro:property name="j5_velocity_limit" value="${radians( 460)}"/>
    <xacro:property name="j6_velocity_limit" value="${radians( 740)}"/>

    <!-- link inertial (TODO: gerçek inertial ile güncellenebilir) -->
    <xacro:macro name="default_inertial" params="mass">
      <inertial>
        <mass value="${mass}" />
        <inertia ixx="1.0" ixy="0.0" ixz="0.0" iyy="1.0" iyz="0.0" izz="1.0" />
      </inertial>
    </xacro:macro>

    <!-- === Link 0 === -->
    <link name="${tf_prefix}base_link">
      <visual>
        <geometry>
          <mesh filename="package://mobile_manipulator_description/meshes/khi_rs/RS005L_J0.STL"/>
        </geometry>
        <material name="White"/>
        <origin rpy="0 0 0" xyz="0 0 0"/>
      </visual>
      <collision>
        <geometry>
          <mesh filename="package://mobile_manipulator_description/meshes/khi_rs/RS005L_J0.STL"/>
        </geometry>
        <material name="White"/>
        <origin rpy="0 0 0" xyz="0 0 0"/>
      </collision>
      <xacro:default_inertial mass="${j0_mass}"/>
    </link>
    
    <joint name="${tf_prefix}base_mount" type="fixed">
      <parent link="${parent}"/>
      <child  link="${tf_prefix}base_link"/>
      <xacro:insert_block name="origin"/>
    </joint>

    

    <link name="${tf_prefix}link1">
      <visual>
        <geometry>
          <mesh filename="package://mobile_manipulator_description/meshes/khi_rs/RS005L_J1.STL"/>
        </geometry>
        <material name="White"/>
        <origin rpy="0 0 0" xyz="0 0 0"/>
      </visual>
      <collision>
        <geometry>
          <mesh filename="package://mobile_manipulator_description/meshes/khi_rs/RS005L_J1.STL"/>
        </geometry>
        <material name="White"/>
        <origin rpy="0 0 0" xyz="0 0 0"/>
      </collision>
      <xacro:default_inertial mass="${j1_mass}"/>
    </link>

    <link name="${tf_prefix}link2">
      <visual>
        <geometry>
          <mesh filename="package://mobile_manipulator_description/meshes/khi_rs/RS005L_J2.STL"/>
        </geometry>
        <material name="White"/>
        <origin xyz="0 0 0" rpy="0 0 0"/>
      </visual>
      <collision>
        <geometry>
          <mesh filename="package://mobile_manipulator_description/meshes/khi_rs/RS005L_J2.STL"/>
        </geometry>
        <material name="White"/>
        <origin xyz="0 0 0" rpy="0 0 0"/>
      </collision>
      <!-- Buradaki typo düzeltildi: 0${j2_mass} -> ${j2_mass} -->
      <xacro:default_inertial mass="${j2_mass}"/>
    </link>

    <link name="${tf_prefix}link3">
      <visual>
        <geometry>
          <mesh filename="package://mobile_manipulator_description/meshes/khi_rs/RS005L_J3.STL"/>
        </geometry>
        <material name="White"/>
        <origin xyz="0 0 0" rpy="0 0 0"/>
      </visual>
      <collision>
        <geometry>
          <mesh filename="package://mobile_manipulator_description/meshes/khi_rs/RS005L_J3.STL"/>
        </geometry>
        <material name="White"/>
        <origin xyz="0 0 0" rpy="0 0 0"/>
      </collision>
      <xacro:default_inertial mass="${j3_mass}"/>
    </link>

    <link name="${tf_prefix}link4">
      <visual>
        <geometry>
          <mesh filename="package://mobile_manipulator_description/meshes/khi_rs/RS005L_J4.STL"/>
        </geometry>
        <material name="White"/>
        <origin xyz="0 0 0" rpy="0 0 0"/>
      </visual>
      <collision>
        <geometry>
          <mesh filename="package://mobile_manipulator_description/meshes/khi_rs/RS005L_J4.STL"/>
        </geometry>
        <material name="White"/>
        <origin xyz="0 0 0" rpy="0 0 0"/>
      </collision>
      <xacro:default_inertial mass="${j4_mass}"/>
    </link>

    <link name="${tf_prefix}link5">
      <visual>
        <geometry>
          <mesh filename="package://mobile_manipulator_description/meshes/khi_rs/RS005L_J5.STL"/>
        </geometry>
        <material name="White"/>
        <origin xyz="0 0 0" rpy="0 0 0"/>
      </visual>
      <collision>
        <geometry>
          <mesh filename="package://mobile_manipulator_description/meshes/khi_rs/RS005L_J5.STL"/>
        </geometry>
        <material name="White"/>
        <origin xyz="0 0 0" rpy="0 0 0"/>
      </collision>
      <xacro:default_inertial mass="${j5_mass}"/>
    </link>

    <link name="${tf_prefix}link6">
      <visual>
        <geometry>
          <mesh filename="package://mobile_manipulator_description/meshes/khi_rs/RS005L_J6.STL"/>
        </geometry>
        <material name="Black"/>
        <origin xyz="0 0 0" rpy="0 0 0"/>
      </visual>
      <collision>
        <geometry>
          <mesh filename="package://mobile_manipulator_description/meshes/khi_rs/RS005L_J6.STL"/>
        </geometry>
        <material name="Black"/>
        <origin xyz="0 0 0" rpy="0 0 0"/>
      </collision>
      <xacro:default_inertial mass="${j6_mass}"/>
    </link>

    <!-- === Link 1 === -->
    <joint name="${tf_prefix}joint1" type="revolute">
      <axis xyz="0 0 -1" rpy="0 0 0" />
      <limit effort="1000.0" lower="${j1_lower_limit}" upper="${j1_upper_limit}" velocity="${j1_velocity_limit}"/>
      <origin xyz="0 0 ${j0_length}" rpy="0 0 0" />
      <parent link="${tf_prefix}base_link"/>
      <child link="${tf_prefix}link1"/>
      <dynamics damping="0.0" friction="0.0"/>
    </joint>

    <!-- === Link 2 === -->
    <joint name="${tf_prefix}joint2" type="revolute">
      <axis xyz="0 0 1" rpy="0 0 0" />
      <limit effort="1000.0" lower="${j2_lower_limit}" upper="${j2_upper_limit}" velocity="${j2_velocity_limit}"/>
      <origin xyz="0 ${j1_length} 0" rpy="0 ${dh_j1_j2_roty*-1} 0" />
      <parent link="${tf_prefix}link1"/>
      <child link="${tf_prefix}link2"/>
      <dynamics damping="0.0" friction="0.0"/>
    </joint>

    

    <!-- === Link 3 === -->
    <joint name="${tf_prefix}joint3" type="revolute">
      <axis xyz="0 0 -1" rpy="0 0 0" />
      <limit effort="1000.0" lower="${j3_lower_limit}" upper="${j3_upper_limit}" velocity="${j3_velocity_limit}"/>
      <origin xyz="${j2_length} 0 0" rpy="0 0 0" />
      <parent link="${tf_prefix}link2"/>
      <child link="${tf_prefix}link3"/>
      <dynamics damping="0.0" friction="0.0"/>
    </joint>

    

    <!-- === Link 4 === -->
    <joint name="${tf_prefix}joint4" type="revolute">
      <axis xyz="0 0 1" rpy="0 0 0" />
      <limit effort="1000.0" lower="${j4_lower_limit}" upper="${j4_upper_limit}" velocity="${j4_velocity_limit}"/>
      <origin xyz="${j31_length} ${j32_length*-1} 0" rpy="0 ${dh_j3_j4_roty} 0" />
      <parent link="${tf_prefix}link3"/>
      <child link="${tf_prefix}link4"/>
      <dynamics damping="0.0" friction="0.0"/>
    </joint>

    

    <!-- === Link 5 === -->
    <joint name="${tf_prefix}joint5" type="revolute">
      <axis xyz="0 0 -1" rpy="0 0 0" />
      <limit effort="1000.0" lower="${j5_lower_limit}" upper="${j5_upper_limit}" velocity="${j5_velocity_limit}"/>
      <origin xyz="0 0 0.26" rpy="0 ${dh_j4_j5_roty*-1} 0" />
      <parent link="${tf_prefix}link4"/>
      <child link="${tf_prefix}link5"/>
      <dynamics damping="0.0" friction="0.0"/>
    </joint>

    

    <!-- === Link 6 === -->
    <joint name="${tf_prefix}joint6" type="revolute">
      <axis xyz="0 0 1" rpy="0 0 0" />
      <limit effort="1000.0" lower="${j6_lower_limit}" upper="${j6_upper_limit}" velocity="${j6_velocity_limit}"/>
      <origin xyz="${j5_length} 0 0" rpy="0 ${dh_j5_j6_roty} 0" />
      <parent link="${tf_prefix}link5"/>
      <child link="${tf_prefix}link6"/>
      <dynamics damping="0.0" friction="0.0"/>
    </joint>

    <!-- ÇEVRESEL BİLEŞENLER -->

  </xacro:macro>
</robot>
